<?xml version="1.0" ?>
<!-- =================================================================================== -->
<!-- |    This document was autogenerated by xacro from robot.xacro                    | -->
<!-- |    EDITING THIS FILE BY HAND IS NOT RECOMMENDED                                 | -->
<!-- =================================================================================== -->
<robot name="robot">
  <material name="black">
    <color rgba="0.0 0.0 0.0 1.0"/>
  </material>
  <material name="blue">
    <color rgba="0.0 0.0 0.8 1.0"/>
  </material>
  <material name="green">
    <color rgba="0.0 0.8 0.0 1.0"/>
  </material>
  <material name="grey">
    <color rgba="0.2 0.2 0.2 1.0"/>
  </material>
  <material name="silver">
    <color rgba="0.9137254901960784 0.9137254901960784 0.8470588235294118 1.0"/>
  </material>
  <material name="orange">
    <color rgba="1.0 0.4235294117647059 0.0392156862745098 1.0"/>
  </material>
  <material name="brown">
    <color rgba="0.8705882352941177 0.8117647058823529 0.7647058823529411 1.0"/>
  </material>
  <material name="red">
    <color rgba="0.8 0.0 0.0 1.0"/>
  </material>
  <material name="white">
    <color rgba="1.0 1.0 1.0 1.0"/>
  </material>
  <material name="body">
    <color rgba="0.73 0.73 0.73 1.0"/>
  </material>
  <material name="lidar">
    <color rgba="0.25 0.7 1 1.0"/>
  </material>
  <link name="base">
    <visual>
      <origin rpy="0 0 0" xyz="0 0 0"/>
      <geometry>
        <mesh filename="../meshes/trunk.STL" scale="1 1 1"/>
      </geometry>
      <material name="body"/>
    </visual>
    <collision>
      <origin rpy="0 0 0" xyz="0 0 0"/>
      <geometry>
        <box size="0.423 0.404 0.252"/>
      </geometry>
    </collision>
    <inertial>
      <origin rpy="0 0 0" xyz="-0.00334 -0.00038 0.0139"/>
      <mass value="64.6"/>
      <inertia ixx="0.7333" ixy="0.00445" ixz="-0.026" iyy="1.45752" iyz="0.0006" izz="1.807"/>
    </inertial>
  </link>
  <!-- Imu is fixed to the base link -->
  <joint name="robot_imu_joint" type="fixed">
    <origin rpy="0. 0. 0." xyz="0. 0. 0."/>
    <parent link="base"/>
    <child link="robot_imu"/>
  </joint>
  <!-- Imu link -->
  <link name="robot_imu">
    <inertial>
      <mass value="0.01"/>
      <origin rpy="0 0 0" xyz="0 0 0"/>
      <inertia ixx="0.000001" ixy="0" ixz="0" iyy="0.000001" iyz="0" izz="0.000001"/>
    </inertial>
    <visual>
      <origin rpy="0 0 0" xyz="0 0 0"/>
      <geometry>
        <box size="0.015 0.015 0.004"/>
      </geometry>
    </visual>
    <material name="orange">
      <color rgba="255 108 10 255"/>
    </material>
  </link>
 
  <joint name="FR_hip_joint" type="revolute">
    <origin rpy="0 0 0" xyz="0.289 -0.1175 0.0005"/>
    <parent link="base"/>
    <child link="FR_hip"/>
    <axis xyz="1 0 0"/>
    <dynamics damping="0" friction="0"/>
    <limit effort="320" lower="-0.87" upper="0.87" velocity="23"/>
  </joint>
  <link name="FR_hip">
    <visual>
      <geometry>
        <mesh filename="../meshes/hip_mirror.STL" scale="1 1 1"/>
      </geometry>
      <material name="grey"/>
    </visual>
    <inertial>
      <origin rpy="0 0 0" xyz="0.0666 0.0083 0.0042"/>
      <mass value="3.8"/>
      <inertia ixx="0.00896" ixy="0.00208" ixz="0.00096" iyy="0.03066" iyz="0.000202" izz="0.02798"/>
    </inertial>
  </link>
  <joint name="FR_thigh_joint" type="revolute">
    <origin rpy="0 0 0" xyz="0.088 -0.16763 0"/>
    <parent link="FR_hip"/>
    <child link="FR_thigh"/>
    <axis xyz="0 1 0"/>
    <dynamics damping="0" friction="0"/>
    <limit effort="320" lower="-1.64" upper="4.69" velocity="23"/>
  </joint>
  <link name="FR_thigh">
    <visual>
      <origin rpy="0 0 0" xyz="0 0 0"/>
      <geometry>
        <mesh filename="../meshes/thigh_mirror.STL" scale="1 1 1"/>
      </geometry>
      <material name="grey"/>
    </visual>
    <collision>
      <origin rpy="0 1.5707963267948966 0" xyz="-0.01 0 -0.16"/>
      <geometry>
        <box size="0.27 0.06 0.08"/>
      </geometry>
    </collision>
    <inertial>
      <origin rpy="0 0 0" xyz="-0.002 0.064 -0.0263"/>
      <mass value="4.66"/>
      <inertia ixx="0.06668" ixy="0" ixz="0.00197" iyy="0.0463" iyz="-0.00057" izz="0.03168"/>
    </inertial>
  </link>
  <joint name="FR_calf_joint" type="revolute">
    <origin rpy="0 0 0" xyz="0 0.004 -0.32"/>
    <parent link="FR_thigh"/>
    <child link="FR_calf"/>
    <axis xyz="0 1 0"/>
    <dynamics damping="0" friction="0"/>
    <limit effort="320" lower="-2.82" upper="-0.43" velocity="14"/>
  </joint>
  <link name="FR_calf">
    <visual>
      <origin rpy="0 0 0" xyz="0 0 0"/>
      <geometry>
        <mesh filename="../meshes/calf.STL" scale="1 1 1"/>
      </geometry>
      <material name="grey"/>
    </visual>
    <collision>
      <origin rpy="0 1.5707963267948966 0" xyz="0 0 -0.16"/>
      <geometry>
        <box size="0.27 0.010000000000000002 0.05"/>
      </geometry>
    </collision>
    <inertial>
      <origin rpy="0 0 0" xyz="0.00434 0.00778 -0.2466"/>
      <mass value="3.54"/>
      <inertia ixx="0.2887" ixy="0" ixz="-0.00393" iyy="0.2885" iyz="-0.00946" izz="0.00516"/>
    </inertial>
  </link>
  <joint name="FR_foot_joint" type="revolute">
    <origin rpy="0 0 0" xyz="0 -0.04163 -0.32"/>
    <parent link="FR_calf"/>
    <child link="FR_foot"/>
    <axis xyz="0 1 0"/>
    <dynamics damping="0" friction="0"/>
    <limit effort="50" lower="-99999" upper="99999" velocity="10"/>
  </joint>
  <link name="FR_foot">
    <visual>
      <origin rpy="0 0 0" xyz="0 0 0"/>
      <geometry>
        <mesh filename="../meshes/wheel_mirror.STL" scale="1 1 1"/>
      </geometry>
      <material name="orange"/>
    </visual>
    <collision>
      <origin rpy="1.5707963267948966 0 0" xyz="0 0 0"/>
      <geometry>
        <cylinder length="0.04" radius="0.1005"/>
      </geometry>
    </collision>
    <inertial>
      <origin rpy="0 0 0" xyz="0.0 0.00298 0.0"/>
      <mass value="1"/>
      <inertia ixx="0.0033" ixy="0.0" ixz="0.0" iyy="0.0063" iyz="0.0" izz="0.0033"/>
    </inertial>
  </link>
 
  <joint name="FL_hip_joint" type="revolute">
    <origin rpy="0 0 0" xyz="0.289 0.1175 0.0005"/>
    <parent link="base"/>
    <child link="FL_hip"/>
    <axis xyz="1 0 0"/>
    <dynamics damping="0" friction="0"/>
    <limit effort="320" lower="-0.87" upper="0.87" velocity="23"/>
  </joint>
  <link name="FL_hip">
    <visual>
      <origin rpy="0 0 0" xyz="0 0 0"/>
      <geometry>
        <mesh filename="../meshes/hip.STL" scale="1 1 1"/>
      </geometry>
      <material name="grey"/>
    </visual>
    <inertial>
      <origin rpy="0 0 0" xyz="0.0666 -0.0083 0.0042"/>
      <mass value="3.8"/>
      <inertia ixx="0.00896" ixy="-0.00208" ixz="0.00096" iyy="0.03066" iyz="-0.000202" izz="0.02798"/>
    </inertial>
  </link>
  <joint name="FL_thigh_joint" type="revolute">
    <origin rpy="0 0 0" xyz="0.088 0.16763 0"/>
    <parent link="FL_hip"/>
    <child link="FL_thigh"/>
    <axis xyz="0 1 0"/>
    <dynamics damping="0" friction="0"/>
    <limit effort="320" lower="-1.64" upper="4.69" velocity="23"/>
  </joint>
  <link name="FL_thigh">
    <visual>
      <origin rpy="0 0 0" xyz="0 0 0"/>
      <geometry>
        <mesh filename="../meshes/thigh.STL" scale="1 1 1"/>
      </geometry>
      <material name="grey"/>
    </visual>
    <collision>
      <origin rpy="0 1.5707963267948966 0" xyz="-0.01 0 -0.16"/>
      <geometry>
        <box size="0.27 0.06 0.08"/>
      </geometry>
    </collision>
    <inertial>
      <origin rpy="0 0 0" xyz="-0.002 -0.064 -0.0263"/>
      <mass value="4.66"/>
      <inertia ixx="0.06668" ixy="0" ixz="0.00197" iyy="0.0463" iyz="0.00057" izz="0.03168"/>
    </inertial>
  </link>
  <joint name="FL_calf_joint" type="revolute">
    <origin rpy="0 0 0" xyz="0 -0.004 -0.32"/>
    <parent link="FL_thigh"/>
    <child link="FL_calf"/>
    <axis xyz="0 1 0"/>
    <dynamics damping="0" friction="0"/>
    <limit effort="320" lower="-2.82" upper="-0.43" velocity="14"/>
  </joint>
  <link name="FL_calf">
    <visual>
      <origin rpy="0 0 0" xyz="0 0 0"/>
      <geometry>
        <mesh filename="../meshes/calf.STL" scale="1 1 1"/>
      </geometry>
      <material name="grey"/>
    </visual>
    <collision>
      <origin rpy="0 1.5707963267948966 0" xyz="0 0 -0.16"/>
      <geometry>
        <box size="0.27 0.010000000000000002 0.05"/>
      </geometry>
    </collision>
    <inertial>
      <origin rpy="0 0 0" xyz="0.00434 0.00778 -0.2466"/>
      <mass value="3.54"/>
      <inertia ixx="0.2887" ixy="0" ixz="-0.00393" iyy="0.2885" iyz="-0.00946" izz="0.00516"/>
    </inertial>
  </link>
  <joint name="FL_foot_joint" type="revolute">
    <origin rpy="0 0 0" xyz="0 0.04163 -0.32"/>
    <parent link="FL_calf"/>
    <child link="FL_foot"/>
    <axis xyz="0 1 0"/>
    <dynamics damping="0" friction="0"/>
    <limit effort="50" lower="-99999" upper="99999" velocity="10"/>
  </joint>
  <link name="FL_foot">
    <visual>
      <origin rpy="0 0 0" xyz="0 0 0"/>
      <geometry>
        <mesh filename="../meshes/wheel.STL" scale="1 1 1"/>
      </geometry>
      <material name="orange"/>
    </visual>
    <collision>
      <origin rpy="1.5707963267948966 0 0" xyz="0 0 0"/>
      <geometry>
        <cylinder length="0.04" radius="0.1005"/>
      </geometry>
    </collision>
    <inertial>
      <origin rpy="0 0 0" xyz="0.0 0.00298 0.0"/>
      <mass value="1"/>
      <inertia ixx="0.0033" ixy="0.0" ixz="0.0" iyy="0.0063" iyz="0.0" izz="0.0033"/>
    </inertial>
  </link>
  
  <joint name="RR_hip_joint" type="revolute">
    <origin rpy="0 0 0" xyz="-0.289 -0.1175 0.0005"/>
    <parent link="base"/>
    <child link="RR_hip"/>
    <axis xyz="1 0 0"/>
    <dynamics damping="0" friction="0"/>
    <limit effort="320" lower="-0.87" upper="0.87" velocity="23"/>
  </joint>
  <link name="RR_hip">
    <visual>
      <origin rpy="0 3.141592653589793 0" xyz="0 0 0"/>
      <geometry>
        <mesh filename="../meshes/hip_mirror.STL" scale="1 1 1"/>
      </geometry>
      <material name="grey"/>
    </visual>
    <inertial>
      <origin rpy="0 0 0" xyz="-0.0666 0.0083 0.0042"/>
      <mass value="3.8"/>
      <inertia ixx="0.00896" ixy="-0.00208" ixz="-0.00096" iyy="0.03066" iyz="0.000202" izz="0.02798"/>
    </inertial>
  </link>
  <joint name="RR_thigh_joint" type="revolute">
    <origin rpy="0 0 0" xyz="-0.088 -0.16763 0"/>
    <parent link="RR_hip"/>
    <child link="RR_thigh"/>
    <axis xyz="0 1 0"/>
    <dynamics damping="0" friction="0"/>
    <limit effort="320" lower="-1.64" upper="4.69" velocity="23"/>
  </joint>
  <link name="RR_thigh">
    <visual>
      <origin rpy="0 0 0" xyz="0 0 0"/>
      <geometry>
        <mesh filename="../meshes/thigh_mirror.STL" scale="1 1 1"/>
      </geometry>
      <material name="grey"/>
    </visual>
    <collision>
      <origin rpy="0 1.5707963267948966 0" xyz="-0.01 0 -0.16"/>
      <geometry>
        <box size="0.27 0.06 0.08"/>
      </geometry>
    </collision>
    <inertial>
      <origin rpy="0 0 0" xyz="-0.002 0.064 -0.0263"/>
      <mass value="4.66"/>
      <inertia ixx="0.06668" ixy="0" ixz="0.00197" iyy="0.0463" iyz="-0.00057" izz="0.03168"/>
    </inertial>
  </link>
  <joint name="RR_calf_joint" type="revolute">
    <origin rpy="0 0 0" xyz="0 0.004 -0.32"/>
    <parent link="RR_thigh"/>
    <child link="RR_calf"/>
    <axis xyz="0 1 0"/>
    <dynamics damping="0" friction="0"/>
    <limit effort="320" lower="-2.82" upper="-0.43" velocity="14"/>
  </joint>
  <link name="RR_calf">
    <visual>
      <origin rpy="0 0 0" xyz="0 0 0"/>
      <geometry>
        <mesh filename="../meshes/calf.STL" scale="1 1 1"/>
      </geometry>
      <material name="grey"/>
    </visual>
    <collision>
      <origin rpy="0 1.5707963267948966 0" xyz="0 0 -0.16"/>
      <geometry>
        <box size="0.27 0.010000000000000002 0.05"/>
      </geometry>
    </collision>
    <inertial>
      <origin rpy="0 0 0" xyz="0.00434 0.00778 -0.2466"/>
      <mass value="3.54"/>
      <inertia ixx="0.2887" ixy="0" ixz="-0.00393" iyy="0.2885" iyz="-0.00946" izz="0.00516"/>
    </inertial>
  </link>
  <joint name="RR_foot_joint" type="revolute">
    <origin rpy="0 0 0" xyz="0 -0.04163 -0.32"/>
    <parent link="RR_calf"/>
    <child link="RR_foot"/>
    <axis xyz="0 1 0"/>
    <dynamics damping="0" friction="0"/>
    <limit effort="50" lower="-99999" upper="99999" velocity="10"/>
  </joint>
  <link name="RR_foot">
    <visual>
      <origin rpy="0 0 0" xyz="0 0 0"/>
      <geometry>
        <mesh filename="../meshes/wheel_mirror.STL" scale="1 1 1"/>
      </geometry>
      <material name="orange"/>
    </visual>
    <collision>
      <origin rpy="1.5707963267948966 0 0" xyz="0 0 0"/>
      <geometry>
        <cylinder length="0.04" radius="0.1005"/>
      </geometry>
    </collision>
    <inertial>
      <origin rpy="0 0 0" xyz="0.0 0.00298 0.0"/>
      <mass value="1"/>
      <inertia ixx="0.0033" ixy="0.0" ixz="0.0" iyy="0.0063" iyz="0.0" izz="0.0033"/>
    </inertial>
  </link>
  
  <joint name="RL_hip_joint" type="revolute">
    <origin rpy="0 0 0" xyz="-0.289 0.1175 0.0005"/>
    <parent link="base"/>
    <child link="RL_hip"/>
    <axis xyz="1 0 0"/>
    <dynamics damping="0" friction="0"/>
    <limit effort="320" lower="-0.87" upper="0.87" velocity="23"/>
  </joint>
  <link name="RL_hip">
    <visual>
      <origin rpy="0 3.141592653589793 0" xyz="0 0 0"/>
      <geometry>
        <mesh filename="../meshes/hip.STL" scale="1 1 1"/>
      </geometry>
      <material name="grey"/>
    </visual>
    <inertial>
      <origin rpy="0 0 0" xyz="-0.0666 -0.0083 0.0042"/>
      <mass value="3.8"/>
      <inertia ixx="0.00896" ixy="0.00208" ixz="-0.00096" iyy="0.03066" iyz="-0.000202" izz="0.02798"/>
    </inertial>
  </link>
  <joint name="RL_thigh_joint" type="revolute">
    <origin rpy="0 0 0" xyz="-0.088 0.16763 0"/>
    <parent link="RL_hip"/>
    <child link="RL_thigh"/>
    <axis xyz="0 1 0"/>
    <dynamics damping="0" friction="0"/>
    <limit effort="320" lower="-1.64" upper="4.69" velocity="23"/>
  </joint>
  <link name="RL_thigh">
    <visual>
      <origin rpy="0 0 0" xyz="0 0 0"/>
      <geometry>
        <mesh filename="../meshes/thigh.STL" scale="1 1 1"/>
      </geometry>
      <material name="grey"/>
    </visual>
    <collision>
      <origin rpy="0 1.5707963267948966 0" xyz="-0.01 0 -0.16"/>
      <geometry>
        <box size="0.27 0.06 0.08"/>
      </geometry>
    </collision>
    <inertial>
      <origin rpy="0 0 0" xyz="-0.002 -0.064 -0.0263"/>
      <mass value="4.66"/>
      <inertia ixx="0.06668" ixy="0" ixz="0.00197" iyy="0.0463" iyz="0.00057" izz="0.03168"/>
    </inertial>
  </link>
  <joint name="RL_calf_joint" type="revolute">
    <origin rpy="0 0 0" xyz="0 -0.004 -0.32"/>
    <parent link="RL_thigh"/>
    <child link="RL_calf"/>
    <axis xyz="0 1 0"/>
    <dynamics damping="0" friction="0"/>
    <limit effort="320" lower="-2.82" upper="-0.43" velocity="14"/>
  </joint>
  <link name="RL_calf">
    <visual>
      <origin rpy="0 0 0" xyz="0 0 0"/>
      <geometry>
        <mesh filename="../meshes/calf.STL" scale="1 1 1"/>
      </geometry>
      <material name="grey"/>
    </visual>
    <collision>
      <origin rpy="0 1.5707963267948966 0" xyz="0 0 -0.16"/>
      <geometry>
        <box size="0.27 0.010000000000000002 0.05"/>
      </geometry>
    </collision>
    <inertial>
      <origin rpy="0 0 0" xyz="0.00434 0.00778 -0.2466"/>
      <mass value="3.54"/>
      <inertia ixx="0.2887" ixy="0" ixz="-0.00393" iyy="0.2885" iyz="-0.00946" izz="0.00516"/>
    </inertial>
  </link>
  <joint name="RL_foot_joint" type="revolute">
    <origin rpy="0 0 0" xyz="0 0.04163 -0.32"/>
    <parent link="RL_calf"/>
    <child link="RL_foot"/>
    <axis xyz="0 1 0"/>
    <dynamics damping="0" friction="0"/>
    <limit effort="50" lower="-99999" upper="99999" velocity="10"/>
  </joint>
  <link name="RL_foot">
    <visual>
      <origin rpy="0 0 0" xyz="0 0 0"/>
      <geometry>
        <mesh filename="../meshes/wheel.STL" scale="1 1 1"/>
      </geometry>
      <material name="orange"/>
    </visual>
    <collision>
      <origin rpy="1.5707963267948966 0 0" xyz="0 0 0"/>
      <geometry>
        <cylinder length="0.04" radius="0.1005"/>
      </geometry>
    </collision>
    <inertial>
      <origin rpy="0 0 0" xyz="0.0 0.00298 0.0"/>
      <mass value="1"/>
      <inertia ixx="0.0033" ixy="0.0" ixz="0.0" iyy="0.0063" iyz="0.0" izz="0.0033"/>
    </inertial>
  </link>
  
</robot>

